<?xml version="1.0" ?>
<sdf version="1.8">
    <model name='my_robot' canonical_link='chassis'>
            <link name='chassis'>
            <pose relative_to='__model__'>0.5 0 0.4 0 0 0</pose>
            <inertial> <!--inertial properties of the link mass, inertia matix-->
                <mass>1.14395</mass>
                <inertia>
                    <ixx>0.095329</ixx>
                    <ixy>0</ixy>
                    <ixz>0</ixz>
                    <iyy>0.381317</iyy>
                    <iyz>0</iyz>
                    <izz>0.476646</izz>
                </inertia>
            </inertial>
            <visual name='visual'>
                <geometry>
                    <box>
                        <size>2.0 1.0 0.5</size>
                    </box>
                </geometry>
                <!--let's add color to our link-->
                <material>
                    <ambient>0.0 0.5 0.5 1</ambient>
                    <diffuse>0.0 0.5 0.5 1</diffuse>
                    <specular>0.0 0.5 0.5 1</specular>
                </material>
            </visual>
            <collision name='collision'>
                <geometry>
                    <box>
                        <size>2.0 1.0 0.5</size>
                    </box>
                </geometry>
            </collision>
            <sensor name="imu_sensor" type="imu">
                <always_on>1</always_on>
                <update_rate>1</update_rate>
                <visualize>true</visualize>
                <topic>imu</topic>
            </sensor>
            <sensor name='gpu_lidar' type='gpu_lidar'>"
                <pose relative_to='lidar_frame'>0 0 0 0 0 0</pose>
                <topic>lidar</topic>
                <update_rate>10</update_rate>
                <ray>
                    <scan>
                        <horizontal>
                            <samples>640</samples>
                            <resolution>1</resolution>
                            <min_angle>-1.396263</min_angle>
                            <max_angle>1.396263</max_angle>
                        </horizontal>
                        <vertical>
                            <samples>1</samples>
                            <resolution>0.01</resolution>
                            <min_angle>0</min_angle>
                            <max_angle>0</max_angle>
                        </vertical>
                    </scan>
                    <range>
                        <min>0.08</min>
                        <max>25.0</max>
                        <resolution>0.01</resolution>
                    </range>
                </ray>
                <always_on>1</always_on>
                <visualize>true</visualize>
            </sensor>
            <sensor name='front_camera_sensor' type='camera'>
                <pose relative_to="chassis">1.05 0 0 0 0.0 0</pose>
                <topic>camera</topic>
                <update_rate>30</update_rate>
                <enable_metrics>false</enable_metrics>
                <camera name='camera'>
                    <pose>0 0 0 0 0 0</pose>
                    <horizontal_fov>1.3962600000000001</horizontal_fov>
                    <image>
                    <width>800</width>
                    <height>800</height>
                    <format>RGB_INT8</format>
                    <anti_aliasing>4</anti_aliasing>
                    </image>
                    <camera_info_topic>__default__</camera_info_topic>
                    <trigger_topic></trigger_topic>
                    <triggered>false</triggered>
                    <clip>
                    <near>0.02</near>
                    <far>300</far>
                    </clip>
                    <save enabled='false'>
                    <path>__default__</path>
                    </save>
                    <visibility_mask>4294967295</visibility_mask>
                    <noise>
                    <type>gaussian</type>
                    <mean>0</mean>
                    <stddev>0.0070000000000000001</stddev>
                    </noise>
                    <distortion>
                    <k1>0</k1>
                    <k2>0</k2>
                    <k3>0</k3>
                    <p1>0</p1>
                    <p2>0</p2>
                    <center>0.5 0.5</center>
                    </distortion>
                    <lens>
                    <type>stereographic</type>
                    <scale_to_hfov>true</scale_to_hfov>
                    <cutoff_angle>1.5708</cutoff_angle>
                    <env_texture_size>256</env_texture_size>
                    </lens>
                    <optical_frame_id></optical_frame_id>
                </camera>
            </sensor>
        </link>
        <link name='left_wheel'>
            <pose relative_to="chassis">-0.5 0.6 0 -1.5707 0 0</pose>
            <inertial>
                <mass>1</mass>
                <inertia>
                    <ixx>0.043333</ixx>
                    <ixy>0</ixy>
                    <ixz>0</ixz>
                    <iyy>0.043333</iyy>
                    <iyz>0</iyz>
                    <izz>0.08</izz>
                </inertia>
            </inertial>
            <visual name='visual'>
                <geometry>
                    <cylinder>
                        <radius>0.4</radius>
                        <length>0.2</length>
                    </cylinder>
                </geometry>
                <material>
                    <ambient>1.0 0.0 1.0 1</ambient>
                    <diffuse>1.0 0.0 1.0 1</diffuse>
                    <specular>1.0 0.0 1.0 1</specular>
                </material>
            </visual>
            <collision name='collision'>
                <geometry>
                    <cylinder>
                        <radius>0.4</radius>
                        <length>0.2</length>
                    </cylinder>
                </geometry>
            </collision>
        </link>
        <link name='right_wheel'>
            <pose relative_to="chassis">-0.5 -0.6 0 -1.5707 0 0</pose> <!--angles are in radian-->
            <inertial>
                <mass>1</mass>
                <inertia>
                    <ixx>0.043333</ixx>
                    <ixy>0</ixy>
                    <ixz>0</ixz>
                    <iyy>0.043333</iyy>
                    <iyz>0</iyz>
                    <izz>0.08</izz>
                </inertia>
            </inertial>
            <visual name='visual'>
                <geometry>
                    <cylinder>
                        <radius>0.4</radius>
                        <length>0.2</length>
                    </cylinder>
                </geometry>
                <material>
                    <ambient>1.0 0.0 1.0 1</ambient>
                    <diffuse>1.0 0.0 1.0 1</diffuse>
                    <specular>1.0 0.0 1.0 1</specular>
                </material>
            </visual>
            <collision name='collision'>
                <geometry>
                    <cylinder>
                        <radius>0.4</radius>
                        <length>0.2</length>
                    </cylinder>
                </geometry>
            </collision>
        </link>
        <frame name="caster_frame" attached_to='chassis'>
            <pose>0.8 0 -0.2 0 0 0</pose>
        </frame>
        <link name='caster'>
            <pose relative_to='caster_frame'/>
            <inertial>
                <mass>1</mass>
                <inertia>
                    <ixx>0.016</ixx>
                    <ixy>0</ixy>
                    <ixz>0</ixz>
                    <iyy>0.016</iyy>
                    <iyz>0</iyz>
                    <izz>0.016</izz>
                </inertia>
            </inertial>
            <visual name='visual'>
                <geometry>
                    <sphere>
                        <radius>0.2</radius>
                    </sphere>
                </geometry>
                <material>
                    <ambient>1.0 1 0.0 1</ambient>
                    <diffuse>1.0 1 0.0 1</diffuse>
                    <specular>1.0 1 0.0 1</specular>
                </material>
            </visual>
            <collision name='collision'>
                <geometry>
                    <sphere>
                        <radius>0.2</radius>
                    </sphere>
                </geometry>
            </collision>
        </link>
        <joint name='left_wheel_joint' type='revolute'>
            <pose relative_to='left_wheel'/>
            <parent>chassis</parent>
            <child>left_wheel</child>
            <axis>
                <xyz expressed_in='__model__'>0 1 0</xyz> <!--can be defined as any frame or even arbitrary frames-->
                <limit>
                    <lower>-1.79769e+308</lower>    <!--negative infinity-->
                    <upper>1.79769e+308</upper>     <!--positive infinity-->
                </limit>
            </axis>
        </joint>
        <joint name='right_wheel_joint' type='revolute'>
            <pose relative_to='right_wheel'/>
            <parent>chassis</parent>
            <child>right_wheel</child>
            <axis>
                <xyz expressed_in='__model__'>0 1 0</xyz>
                <limit>
                    <lower>-1.79769e+308</lower>    <!--negative infinity-->
                    <upper>1.79769e+308</upper>     <!--positive infinity-->
                </limit>
            </axis>
        </joint>
        <joint name='caster_wheel' type='ball'>
            <parent>chassis</parent>
            <child>caster</child>
        </joint>
        <frame name="lidar_frame" attached_to='chassis'>
            <pose>0.8 0 0.5 0 0 0</pose>
        </frame>
        <plugin
            filename="libignition-gazebo-diff-drive-system.so"
            name="ignition::gazebo::systems::DiffDrive">
            <left_joint>left_wheel_joint</left_joint>
            <right_joint>right_wheel_joint</right_joint>
            <wheel_separation>1.2</wheel_separation>
            <wheel_radius>0.4</wheel_radius>
            <odom_publish_frequency>1</odom_publish_frequency>
            <topic>cmd_vel</topic>
        </plugin>
        <plugin filename="libignition-gazebo-triggered-publisher-system.so"
                name="ignition::gazebo::systems::TriggeredPublisher">
            <input type="ignition.msgs.Int32" topic="/keyboard/keypress">
                <match field="data">87</match>
            </input>
            <output type="ignition.msgs.Twist" topic="/cmd_vel">
                linear: {x: 2.0}, angular: {z: 0.0}
            </output>
        </plugin>
                    <plugin filename="libignition-gazebo-triggered-publisher-system.so"
                name="ignition::gazebo::systems::TriggeredPublisher">
            <input type="ignition.msgs.Int32" topic="/keyboard/keypress">
                <match field="data">83</match>
            </input>
            <output type="ignition.msgs.Twist" topic="/cmd_vel">
                linear: {x: -1.0}, angular: {z: 0.0}
            </output>
        </plugin>
                    <plugin filename="libignition-gazebo-triggered-publisher-system.so"
                name="ignition::gazebo::systems::TriggeredPublisher">
            <input type="ignition.msgs.Int32" topic="/keyboard/keypress">
                <match field="data">65</match>
            </input>
            <output type="ignition.msgs.Twist" topic="/cmd_vel">
                linear: {x: 0.0}, angular: {z: 0.5}
            </output>
        </plugin>
                    <plugin filename="libignition-gazebo-triggered-publisher-system.so"
                name="ignition::gazebo::systems::TriggeredPublisher">
            <input type="ignition.msgs.Int32" topic="/keyboard/keypress">
                <match field="data">68</match>
            </input>
            <output type="ignition.msgs.Twist" topic="/cmd_vel">
                linear: {x: 0.0}, angular: {z: -0.5}
            </output>
        </plugin>
    </model>
</sdf>